Workbook
Name NativeTimeline_Criada: #N/A

Sheet Ideias Canceladas
A1: Número | B1: Descrição curta | C1: Status | D1: Enviado por | E1: Categoria | F1: Sub categoria | G1: Criada | H1: Área de trabalho | I1: Atualizado | J1: Atribuído | K1: Grupo de atribuição | L1: Grupo | M1: Motivo do Cancelamento
A2: FB0096684 | B2: coloca o ponto de almoço automático | C2: Cancelado | D2: Julho Silva | E2: Pequena mudança local | F2: Cost (GE, rework) | G2: 45682.48 | H2: 01. JDE CAFES DO BRASIL UNIDADE PIUMHI | I2: 45861.305 | K2: IDEIAS-MELHORIA CONTÍNUA | L2: =_xlfn.XLOOKUP(TAB.cancelada[[#This Row],[Número]],'tabela ideias'!A:A,'tabela ideias'!O:O,"Não encontrado") -> OPERAÇÃO
A3: FB0103691 | B3: mudar câmara fria de lugar | C3: Cancelado | D3: Fabricio Brant | E3: Pequena mudança local | F3: Safety - Health | G3: 45747.209 | H3: 01. LINHA 01 | I3: 45861.471 | K3: IDEIAS-VACUO | L3: =_xlfn.XLOOKUP(TAB.cancelada[[#This Row],[Número]],'tabela ideias'!A:A,'tabela ideias'!O:O,"Não encontrado") -> OPERAÇÃO
A4: FB0104140 | B4: Peneira vibratória para moega de reprocesso da moagem | C4: Cancelado | D4: Pedro Ferreira | E4: Pequena mudança local | F4: Processo | G4: 45750.48 | H4: 03. MOAGEM | I4: 45959.387 | K4: IDEIAS-PROCESSOS | L4: =_xlfn.XLOOKUP(TAB.cancelada[[#This Row],[Número]],'tabela ideias'!A:A,'tabela ideias'!O:O,"Não encontrado") -> ADM/TÉCNICO/ASSISTENTE/ESTAG.
A5: FB0106437 | B5: criar ponto superior de tomada para o ventilador | C5: Cancelado | D5: Weverton Medeiro | E5: Pequena mudança local | F5: Safety - Health | G5: 45773.69 | H5: 05. LINHA 05 | I5: 45959.474 | K5: IDEIAS-ALMOFADA | L5: =_xlfn.XLOOKUP(TAB.cancelada[[#This Row],[Número]],'tabela ideias'!A:A,'tabela ideias'!O:O,"Não encontrado") -> OPERAÇÃO
A6: FB0106984 | B6: Sensor de presença | C6: Cancelado | D6: Vitor Xavier | E6: Pequena mudança local | F6: Processo | G6: 45778.083 | H6: 07. LINHA 07 | I6: 45852.479 | K6: IDEIAS-PROCESSOS | L6: =_xlfn.XLOOKUP(TAB.cancelada[[#This Row],[Número]],'tabela ideias'!A:A,'tabela ideias'!O:O,"Não encontrado") -> OPERAÇÃO
A7: FB0107019 | B7: Peneira vibratória para moega de reprocesso da moagem | C7: Cancelado | D7: Pedro Ferreira | E7: Pequena mudança local | F7: Processo | G7: 45778.453 | H7: 01. MOINHO 01 | I7: 45939.578 | K7: IDEIAS-PROCESSOS | L7: =_xlfn.XLOOKUP(TAB.cancelada[[#This Row],[Número]],'tabela ideias'!A:A,'tabela ideias'!O:O,"Não encontrado") -> ADM/TÉCNICO/ASSISTENTE/ESTAG.
A8: FB0107098 | B8: Uma das bombas de vácuo , desliga com frequência | C8: Cancelado | D8: Romilda Cunha | E8: Pequena mudança local | F8: Cost (GE, rework) | G8: 45779.737 | H8: 01. LINHA 01 | I8: 45861.471 | K8: IDEIAS-VACUO | L8: =_xlfn.XLOOKUP(TAB.cancelada[[#This Row],[Número]],'tabela ideias'!A:A,'tabela ideias'!O:O,"Não encontrado") -> OPERAÇÃO
A9: FB0115697 | B9: obter algum carrinho ou algo para ajudar virar os tambores de rejeitos na caçamba | C9: Cancelado | D9: Ruth Alves | E9: Pequena mudança local | F9: Safety - Health | G9: 45862.095 | H9: 04. EMPACOTAMENTO | I9: 45933.429 | K9: IDEIAS-ALMOFADA | L9: =_xlfn.XLOOKUP(TAB.cancelada[[#This Row],[Número]],'tabela ideias'!A:A,'tabela ideias'!O:O,"Não encontrado") -> OPERAÇÃO
A10: FB0116922 | B10: na PKD não tem um acessório específico para apertar as aparas . | C10: Cancelado | D10: Angela Santos | E10: Pequena mudança local | F10: Qualidade | G10: 45874.238 | H10: 05. LINHA 05 | I10: 45960.371 | K10: IDEIAS-ALMOFADA | L10: =_xlfn.XLOOKUP(TAB.cancelada[[#This Row],[Número]],'tabela ideias'!A:A,'tabela ideias'!O:O,"Não encontrado") -> OPERAÇÃO
A11: FB0107079 | B11: manômetro de pressão | C11: Cancelado | D11: Sara Lobato | E11: Pequena mudança local | F11: Processo | G11: 45779.472 | H11: 05. LINHA 05 | I11: 45945.348 | J11: Relton Moraes | K11: IDEIAS-ALMOFADA | L11: =_xlfn.XLOOKUP(TAB.cancelada[[#This Row],[Número]],'tabela ideias'!A:A,'tabela ideias'!O:O,"Não encontrado") -> OPERAÇÃO
A12: FB0122221 | B12: Suporte | C12: Cancelado | D12: Vitor Xavier | E12: Pequena mudança local | F12: Organisation of work | L12: =_xlfn.XLOOKUP(TAB.cancelada[[#This Row],[Número]],'tabela ideias'!A:A,'tabela ideias'!O:O,"Não encontrado") -> OPERAÇÃO
A13: FB0131366 | B13: ter um suporte com uma placa informando qual café está moendo nos moinhos que tem as moegas. | C13: Cancelado | D13: Ruth Fonseca | E13: Pequena mudança local | F13: Qualidade | G13: 46002.964 | H13: 04. EMPACOTAMENTO | I13: 46224.687 | J13: Angelina Destefani | K13: APROVADORES DE IDEIAS | L13: =_xlfn.XLOOKUP(TAB.cancelada[[#This Row],[Número]],'tabela ideias'!A:A,'tabela ideias'!O:O,"Não encontrado") -> OPERAÇÃO
A14: FB0100188 | B14: instalar botoeira de emergencia na esteira do zero hora | C14: Cancelado | E14: Pequena mudança local | F14: Safety - Health | G14: 45714.34 | H14: 01. LINHA 01 | I14: 46276.538 | J14: Andre Mendes Costa | K14: APROVADORES DE IDEIAS | L14: =_xlfn.XLOOKUP(TAB.cancelada[[#This Row],[Número]],'tabela ideias'!A:A,'tabela ideias'!O:O,"Não encontrado") -> 0
A15: FB0110676 | B15: Compra de micrômetro. | C15: Cancelado | D15: Douglas Destefani | E15: Pequena mudança local | F15: Qualidade | G15: 45813.52 | H15: 09.16 Qualidade CQ | I15: 46276.554 | J15: Tais Costa | K15: APROVADORES DE IDEIAS | L15: =_xlfn.XLOOKUP(TAB.cancelada[[#This Row],[Número]],'tabela ideias'!A:A,'tabela ideias'!O:O,"Não encontrado") -> OPERAÇÃO
A16: FB0119798 | B16: correias das Raumak e fabrimas | C16: Cancelado | D16: Thais Souza | E16: Pequena mudança local | F16: Processo | G16: 45903.654 | H16: 05. LINHA 05 | I16: 46276.586 | J16: Ana Martins | K16: APROVADORES DE IDEIAS | L16: =_xlfn.XLOOKUP(TAB.cancelada[[#This Row],[Número]],'tabela ideias'!A:A,'tabela ideias'!O:O,"Não encontrado") -> OPERAÇÃO
A17: FB0104724 | B17: elevador de canecas 1 e 3 está com vazamento de café | C17: Cancelado | D17: Alex Teixeira | E17: Pequena mudança local | F17: Organisation of work | G17: 45756.75 | H17: 03. MOAGEM | I17: 46188.573 | J17: Anderson Santana | K17: IDEIAS-PROCESSOS | L17: =_xlfn.XLOOKUP(TAB.cancelada[[#This Row],[Número]],'tabela ideias'!A:A,'tabela ideias'!O:O,"Não encontrado") -> OPERAÇÃO
A18: FB0138051 | B18: fazer um claviculário de segurança com as chaves das escadas marinheiro no alarme de incêndio | C18: Cancelado | D18: Arthur Silva | E18: Pequena mudança local | F18: Safety - Health | G18: 46064.582 | H18: 09.19 SALA DE PRODUTOS QUÍMICOS | I18: 46098.651 | K18: IDEIAS-SHE | L18: =_xlfn.XLOOKUP(TAB.cancelada[[#This Row],[Número]],'tabela ideias'!A:A,'tabela ideias'!O:O,"Não encontrado") -> ADM/TÉCNICO/ASSISTENTE/ESTAG.
A19: FB0128543 | B19: Sistema de segurança rosca película | C19: Cancelado | D19: Moises Costa | E19: Pequena mudança local | F19: Cost (GE, rework) | G19: 45980.398 | H19: 02. TORREFAÇÃO | I19: 46143.553 | K19: IDEIAS-PROCESSOS | L19: =_xlfn.XLOOKUP(TAB.cancelada[[#This Row],[Número]],'tabela ideias'!A:A,'tabela ideias'!O:O,"Não encontrado") -> OPERAÇÃO
A20: FB0114559 | B20: acesso a parte superior dos silos | C20: Cancelado | D20: Valdeci Simoes | E20: Pequena mudança local | F20: Organisation of work | G20: 45849.872 | H20: 09.19 SALA DE PRODUTOS QUÍMICOS | I20: 46120.703 | K20: IDEIAS-SHE | L20: =_xlfn.XLOOKUP(TAB.cancelada[[#This Row],[Número]],'tabela ideias'!A:A,'tabela ideias'!O:O,"Não encontrado") -> OPERAÇÃO
A21: FB0143304 | B21: Solicitação de isenção da taxa de lixo junto à prefeitura, considerando que a empresa realiza descarte de resíduos por empresa especializada. | C21: Cancelado | D21: Ana Pereira | E21: Pequena mudança local | F21: Cost (GE, rework) | G21: 46107.547 | H21: 06. ADMINISTRATIVO | I21: 46205.597 | J21: Samuel Camargos | K21: APROVADORES DE IDEIAS | L21: =_xlfn.XLOOKUP(TAB.cancelada[[#This Row],[Número]],'tabela ideias'!A:A,'tabela ideias'!O:O,"Não encontrado") -> ADM/TÉCNICO/ASSISTENTE/ESTAG.
A22: FB0088501 | B22: Melhoria no óculos de segurança | C22: Cancelado | D22: Edvaldo Silva | E22: Pequena mudança local | F22: Safety - Health | G22: 45608.788 | H22: 09.19 SALA DE PRODUTOS QUÍMICOS | I22: 46099.4 | K22: IDEIAS-SHE | L22: =_xlfn.XLOOKUP(TAB.cancelada[[#This Row],[Número]],'tabela ideias'!A:A,'tabela ideias'!O:O,"Não encontrado") -> OPERAÇÃO
A23: FB0132034 | B23: Inclusão de atividade no CIL | C23: Cancelado | D23: Relton Moraes | E23: Pequena mudança local | F23: Processo | G23: 46008.632 | H23: 04. EMPACOTAMENTO | I23: 46156.618 | J23: Bianca Silva | K23: APROVADORES DE IDEIAS | L23: =_xlfn.XLOOKUP(TAB.cancelada[[#This Row],[Número]],'tabela ideias'!A:A,'tabela ideias'!O:O,"Não encontrado") -> ADM/TÉCNICO/ASSISTENTE/ESTAG.
A24: FB0102939 | B24: TREINAMENTO SCRIPT | C24: Cancelado | D24: Aline Fernandes | E24: Pequena mudança local | F24: Organisation of work | G24: 45740.636 | H24: 01. JDE CAFES DO BRASIL UNIDADE PIUMHI | I24: 46170.51 | J24: Luzia Rodrigues | K24: IDEIAS-MELHORIA CONTÍNUA | L24: =_xlfn.XLOOKUP(TAB.cancelada[[#This Row],[Número]],'tabela ideias'!A:A,'tabela ideias'!O:O,"Não encontrado") -> ADM/TÉCNICO/ASSISTENTE/ESTAG.
A25: FB0139843 | B25: facilita o acesso aos bojos sem a necessidade de PT | C25: Cancelado | D25: Alex Teixeira | E25: Grande mudança local | F25: Safety - Health | G25: 46080.341 | H25: 03. MOAGEM | I25: 46132.764 | K25: IDEIAS-PROCESSOS | L25: =_xlfn.XLOOKUP(TAB.cancelada[[#This Row],[Número]],'tabela ideias'!A:A,'tabela ideias'!O:O,"Não encontrado") -> OPERAÇÃO
A26: FB0125662 | B26: Criar instruções para as sirenes das Fabrimas (troca de Silo) | C26: Cancelado | D26: Pedro Ferreira | E26: Pequena mudança local | F26: Cost (GE, rework) | G26: 45957.475 | H26: 04. EMPACOTAMENTO | I26: 46156.666 | K26: APROVADORES DE IDEIAS | L26: =_xlfn.XLOOKUP(TAB.cancelada[[#This Row],[Número]],'tabela ideias'!A:A,'tabela ideias'!O:O,"Não encontrado") -> ADM/TÉCNICO/ASSISTENTE/ESTAG.
A27: FB0124354 | B27: Manual com imagens e passos para a inserção da bobina na fabrima | C27: Cancelado | D27: Valeria Yanez | E27: Pequena mudança local | F27: Organisation of work | G27: 45945.413 | H27: 04. EMPACOTAMENTO | I27: 46156.633 | J27: Tais Costa | K27: APROVADORES DE IDEIAS | L27: =_xlfn.XLOOKUP(TAB.cancelada[[#This Row],[Número]],'tabela ideias'!A:A,'tabela ideias'!O:O,"Não encontrado") -> ADM/TÉCNICO/ASSISTENTE/ESTAG.
A28: FB0147886 | B28: colocar uma tomada nesse local | C28: Cancelado | D28: Luiz H Silva | E28: Pequena mudança local | F28: Organisation of work | G28: 46141.31 | H28: 03. MOAGEM | I28: 46237.432 | J28: Ana Martins | K28: APROVADORES DE IDEIAS | L28: =_xlfn.XLOOKUP(TAB.cancelada[[#This Row],[Número]],'tabela ideias'!A:A,'tabela ideias'!O:O,"Não encontrado") -> OPERAÇÃO
A29: FB0154914 | B29: Substituição dos sensores magnéticos das portas por modelos com LED de indicação visual, facilitando a identificação de portas abertas, mal fechadas ou sensores | C29: Cancelado | D29: Igor Sousa | E29: Grande mudança local | F29: Product | G29: 46188.623 | H29: 01. JDE CAFES DO BRASIL UNIDADE PIUMHI | I29: 46192.456 | K29: IDEIAS-MELHORIA CONTÍNUA | L29: =_xlfn.XLOOKUP(TAB.cancelada[[#This Row],[Número]],'tabela ideias'!A:A,'tabela ideias'!O:O,"Não encontrado") -> ADM/TÉCNICO/ASSISTENTE/ESTAG.
A30: FB0086839 | B30: Ligação independente para codificadora de caixas | C30: Cancelado | D30: Michelle Faria | E30: Pequena mudança local | F30: Processo | G30: 45594.157 | H30: 01. LINHA 01 | I30: 45859.447 | J30: Igor Sousa | K30: IDEIAS-VACUO | L30: =_xlfn.XLOOKUP(TAB.cancelada[[#This Row],[Número]],'tabela ideias'!A:A,'tabela ideias'!O:O,"Não encontrado") -> ADM/TÉCNICO/ASSISTENTE/ESTAG.
A31: FB0087245 | B31: colocar as limpeza t3 cil | C31: Cancelado | D31: Julho Silva | E31: Pequena mudança local | F31: Qualidade | G31: 45596.582 | H31: 02. TORREFAÇÃO | I31: 45811.457 | J31: Priscilla Araujo | K31: IDEIAS-PROCESSOS | L31: =_xlfn.XLOOKUP(TAB.cancelada[[#This Row],[Número]],'tabela ideias'!A:A,'tabela ideias'!O:O,"Não encontrado") -> OPERAÇÃO

Sheet tabela ideias
A1: Número | B1: Descrição curta | C1: Status | D1: Descrição | E1: Enviado por | F1: Categoria | G1: Sub categoria | H1: Criada | I1: Área de trabalho | J1: Atualizado | K1: Atribuído a | L1: Grupo de atribuição | M1: Fechado | N1: Status controle interno | O1: Grupo | P1: canceladas
A2: FB0076323 | B2: Escada dando acesso aos Detectores de Metais | C2: Cancelado | D2: Uma Escada facilitando o acesso aos Detectores de Metais do lado da Fabrima 05 | E2: Isaias Macedo | F2: Pequena mudança local | G2: Organisation of work | H2: 45506.412 | I2: 04. EMPACOTAMENTO | J2: 45552.653 | L2: APROVADORES DE IDEIAS | M2: 45552.653 | N2: Cancelado | O2: =_xlfn.XLOOKUP(TAB.IDEIAS.TOTAL[[#This Row],[Enviado por]],'BASE DMOS'!A:A,'BASE DMOS'!C:C,"Não encontrado") -> OPERAÇÃO | P2: Cancelada
A3: FB0076530 | B3: Isolamento do Vão da Escada Mesanino PKD | C3: Fechado | D3: Devido ao no leaut dos contêiner foi necessário retirar um móvel que havia debaixo do vão da escada ficando um local aberto possibilitando a passagem por baixo da escada em um ponto onde existe a possibilidade de colisão com o rosto ou cabeça. Devido. a necessidade de isolamento podemos aproveitar essa espaço com um armário um com suporte para um bebedouro, e a guarda de utensílios. | E3: Patrick Pessoa | F3: Pequena mudança local | G3: Safety - Health | H3: 45509.402 | I3: 01. LINHA 01 | J3: 45839.432 | K3: Bianca Silva | L3: IDEIAS-VACUO | M3: 45839.432 | N3: Fechado | O3: =_xlfn.XLOOKUP(TAB.IDEIAS.TOTAL[[#This Row],[Enviado por]],'BASE DMOS'!A:A,'BASE DMOS'!C:C,"Não encontrado") -> OPERAÇÃO
A4: FB0076596 | B4: Avaliar relatório de inspeção do ciclones de cinza e película se é pra inspecionar ou retira da folhas o formulários… | C4: Resolvido | D4: Hoje não e feito a inspeção de cinza e película do relatório(FRM-07-016) foi feito uma melhoria colocando sensor de presença na rosca atuando alarme no supervisório quando a caçamba de película está cheia …. Sugiro que seja retirado esta página | E4: Edvan Santos | F4: Pequena mudança local | G4: Processo | H4: 45510.23 | I4: 02. TORREFAÇÃO | J4: 46142.688 | K4: Tiago Carvalho | L4: IDEIAS-PROCESSOS | N4: Resolvido | O4: =_xlfn.XLOOKUP(TAB.IDEIAS.TOTAL[[#This Row],[Enviado por]],'BASE DMOS'!A:A,'BASE DMOS'!C:C,"Não encontrado") -> OPERAÇÃO
A5: FB0076597 | B5: moega de reprocesso e dosagem de café | C5: Cancelado | D5: Moega de reprocesso e dosagem e um processo de melhorar e facilitar o reprocesso de café dos turnos agilizando toda etapa do café para seu devido silo de pó. Para esta melhoria seria utilizado algumas peças que estão obsoletas da linha de grãos e da extratora antiga. | E5: Luiz H Silva | F5: Pequena mudança local | G5: Processo | H5: 45510.246 | I5: 03. MOAGEM | J5: 46140.566 | L5: IDEIAS-PROCESSOS | M5: 46140.566 | N5: Cancelado | O5: =_xlfn.XLOOKUP(TAB.IDEIAS.TOTAL[[#This Row],[Enviado por]],'BASE DMOS'!A:A,'BASE DMOS'!C:C,"Não encontrado") -> OPERAÇÃO
A6: FB0076655 | B6: mesa de pacotes para analise | C6: Fechado | D6: Realizar a confecção de um adesivo referente as numerações das câmaras de vácuo e colocar na mesa de recolhimento de pacotes para análise para posicionamento dos pacotes referente a cada câmara . O adesivo deverá ser confeccionado com impressão da direita para esquerda para acompanhar a forma que pacote sai da roda de vácuo e com é retirado pelos operadores Da seguinte forma de 1 a 4 de 5 a 8 é demais na sequencia até finalizar as 28 câmaras Os pacotes são retirados de 4 a 4 por vez. Pedro Ferreira: Ideia realizada, porém, falta o operador colar os adesivos na mesa. | E6: Patrick Pessoa | F6: Pequena mudança local | G6: Qualidade | H6: 45510.603 | I6: 01. LINHA 01 | J6: 45901.481 | K6: Bianca Silva | L6: IDEIAS-VACUO | M6: 45901.481 | N6: Fechado | O6: =_xlfn.XLOOKUP(TAB.IDEIAS.TOTAL[[#This Row],[Enviado por]],'BASE DMOS'!A:A,'BASE DMOS'!C:C,"Não encontrado") -> OPERAÇÃO
A7: FB0076876 | B7: Claviculário almoxarifado | C7: Fechado | D7: Colocar claviculário com todas as chaves dos armários e portões do almoxarifado numeradas e em ordem, para restringir acesso aos materiais. | E7: Sarah Teixeira | F7: Pequena mudança local | G7: Organisation of work | H7: 45512.688 | I7: 09.1 ALMOXARIFADO | J7: 45523.563 | K7: Sarah Teixeira | L7: IDEIAS-CAFÉ CRÚ | M7: 45523.563 | N7: Fechado | O7: =_xlfn.XLOOKUP(TAB.IDEIAS.TOTAL[[#This Row],[Enviado por]],'BASE DMOS'!A:A,'BASE DMOS'!C:C,"Não encontrado") -> ADM/TÉCNICO/ASSISTENTE/ESTAG.
A8: FB0076877 | B8: Criação de Forms para registro de saídas de almoxarifado | C8: Fechado | D8: Criação de Forms para registro de saídas de almoxarifado, facilitando para quem precisa retirar materiais quando não tem almoxarife para fazer os registros. | E8: Sarah Teixeira | F8: Pequena mudança local | G8: Organisation of work | H8: 45512.694 | I8: 09.1 ALMOXARIFADO | J8: 45527.625 | K8: Sarah Teixeira | L8: IDEIAS-CAFÉ CRÚ | M8: 45527.625 | N8: Fechado | O8: =_xlfn.XLOOKUP(TAB.IDEIAS.TOTAL[[#This Row],[Enviado por]],'BASE DMOS'!A:A,'BASE DMOS'!C:C,"Não encontrado") -> ADM/TÉCNICO/ASSISTENTE/ESTAG. | P8: cancela
A9: FB0076880 | B9: Suporte para etiquetas de fardo | C9: Fechado | D9: Colocar um suporte para colocar as etiquetas dos fardos na parede do CQ, trazer as etiquetas para mais próximo ao almoxarifado e organizar melhor | E9: Sarah Teixeira | F9: Pequena mudança local | G9: Organisation of work | H9: 45512.704 | I9: 09.1 ALMOXARIFADO | J9: 45639.63 | K9: Sarah Teixeira | L9: IDEIAS-CAFÉ CRÚ | M9: 45639.63 | N9: Fechado | O9: =_xlfn.XLOOKUP(TAB.IDEIAS.TOTAL[[#This Row],[Enviado por]],'BASE DMOS'!A:A,'BASE DMOS'!C:C,"Não encontrado") -> ADM/TÉCNICO/ASSISTENTE/ESTAG.
A10: FB0076937 | B10: Retornar com os Teclados e Mouse sem fio | C10: Cancelado | D10: Retornar Mouse e Teclados sem fio,para facilitar o uso sem precisar utilizar suporte para Mouse e não ocupar tanto espaço na mesa | E10: Isaias Macedo | F10: Pequena mudança local | G10: Organisation of work | H10: 45513.305 | I10: 04. LINHA 04 | J10: 45769.669 | L10: APROVADORES DE IDEIAS | M10: 45769.669 | N10: Cancelado | O10: =_xlfn.XLOOKUP(TAB.IDEIAS.TOTAL[[#This Row],[Enviado por]],'BASE DMOS'!A:A,'BASE DMOS'!C:C,"Não encontrado") -> OPERAÇÃO
A11: FB0076944 | B11: Mola Aérea Para Fechamento De Portas Automática - Almoxarifado | C11: Fechado | D11: Colocar uma Mola Aérea Para Fechamento De Portas Automática nas portas do almoxarifado, o fluxo de mecânicos é muito grande e deixam a porta aberta ao sair, se fazendo necessário parar as atividades para fechar a porta. | E11: Sarah Teixeira | F11: Pequena mudança local | G11: Safety - Health | H11: 45513.343 | I11: 09.1 ALMOXARIFADO | J11: 45531.609 | K11: Sarah Teixeira | L11: IDEIAS-CAFÉ CRÚ | M11: 45531.609 | N11: Fechado | O11: =_xlfn.XLOOKUP(TAB.IDEIAS.TOTAL[[#This Row],[Enviado por]],'BASE DMOS'!A:A,'BASE DMOS'!C:C,"Não encontrado") -> ADM/TÉCNICO/ASSISTENTE/ESTAG.
A12: FB0077045 | B12: aplicativo de RO | C12: Resolvido | D12: Colocar uma opção de fotografia no aplicativo de RO para melhor visualização da ocorrência, assim o reporte ficará mais claro pra as pessoas que irão conduzir uma RCA, trazendo uma transparência no que de fato ocorreu e agilidade na tratativa para que seja discutido em OPS. | E12: Edvan Santos | F12: Pequena mudança local | G12: Qualidade | H12: 45516.215 | I12: 09.16 Qualidade CQ | J12: 45807.392 | L12: IDEIAS-QUALIDADE | N12: Resolvido | O12: =_xlfn.XLOOKUP(TAB.IDEIAS.TOTAL[[#This Row],[Enviado por]],'BASE DMOS'!A:A,'BASE DMOS'!C:C,"Não encontrado") -> OPERAÇÃO
A13: FB0077070 | B13: Caixa box não abre | C13: Em andamento | D13: Realizar um sistema de parada na encaixotadora . Caso a caixa box venha colada no interior ela não abre com isso o sensor de parada do magazine não atua e com isso ela passa fechada e com isso fica enroscada nas guias de fechamento da abas laterais com essa falha ocorre o amassamento de pacotes da caixa que vem subsequente ocorrendo perda de pacotes e caixas é risco de quebra do equipamento o esforço ou soltar a corrente principal . OBS Ideia já foi discutida com Igor da Programação. Ana, por favor, programar com o Igor/Eliezer, para realização. | E13: Patrick Pessoa | F13: Pequena mudança local | G13: Cost (GE, rework) | H13: 45516.386 | I13: 01. LINHA 01 | J13: 46202.758 | K13: Ana Martins | L13: APROVADORES DE IDEIAS | N13: Aguardando Execução | O13: =_xlfn.XLOOKUP(TAB.IDEIAS.TOTAL[[#This Row],[Enviado por]],'BASE DMOS'!A:A,'BASE DMOS'!C:C,"Não encontrado") -> OPERAÇÃO
A14: FB0077079 | B14: Sistema Alarme Sonoro e Luminoso | C14: Fechado | D14: Necessidade de colocar um sistema de alarme Sonoro e luminoso no sistema da encaixotadora . Que o momento que ocorrer a falha ele alerte os operadores caso eles estejam desempenhando outra atividade no momento da falha. OBS Ideia discutida com Igor Programação | E14: Patrick Pessoa | F14: Pequena mudança local | G14: Cost (GE, rework) | H14: 45516.398 | I14: 01. LINHA 01 | J14: 45839.432 | K14: Igor Sousa | L14: IDEIAS-VACUO | M14: 45839.432 | N14: Fechado | O14: =_xlfn.XLOOKUP(TAB.IDEIAS.TOTAL[[#This Row],[Enviado por]],'BASE DMOS'!A:A,'BASE DMOS'!C:C,"Não encontrado") -> OPERAÇÃO
A15: FB0077133 | B15: Código de parada alarme de incêndio | C15: Cancelado | D15: Criar um código de parada para quando o brigadista precisar se ausentar da máquina devido ao acionamento do alarme e houver intercorrência e não tiver ninguém para reveza-lo no momento. | E15: Vinicius De Oliveira | F15: Pequena mudança local | G15: Cost (GE, rework) | H15: 45517.006 | I15: 05. LINHA 05 | J15: 45551.689 | L15: APROVADORES DE IDEIAS | M15: 45551.689 | N15: Cancelado | O15: =_xlfn.XLOOKUP(TAB.IDEIAS.TOTAL[[#This Row],[Enviado por]],'BASE DMOS'!A:A,'BASE DMOS'!C:C,"Não encontrado") -> OPERAÇÃO
A16: FB0077202 | B16: abridor de abas encaixotadora | C16: Fechado | D16: Foi realizada nova confecção de abridores de aba , com ângulo de 45 graus para melhorar abertura da caixa , assim voltando com as condições da máquina de base. Protótipo está em funcionamento feito do material de acrílico e estando com bons resultados na máquina. Participantes . Wesley,Patrick,Arthur,Mário rizo | E16: Wesley J Silva | F16: Pequena mudança local | G16: Cost (GE, rework) | H16: 45517.36 | I16: 01. LINHA 01 | J16: 45594.547 | L16: IDEIAS-VACUO | M16: 45594.547 | N16: Fechado | O16: =_xlfn.XLOOKUP(TAB.IDEIAS.TOTAL[[#This Row],[Enviado por]],'BASE DMOS'!A:A,'BASE DMOS'!C:C,"Não encontrado") -> OPERAÇÃO
A17: FB0077203 | B17: Expulsador de caixa box | C17: Fechado | D17: Realizar o desenvolvimento de acionamento manual no expulsador da balança de peso. Para quando ocorre pequena falha no robô o operador possa utilizar o acionamento manual para expulsar caixa sem que haja parada de máquina. Ideia: Discutida com Igor Santos Programação , Realmente é uma ótima ideia, porém todo circuito de NR12 esta interligado com o robô para ser realizado precisa a trazer uma empresa autorizada em NR12 e refazer todo circuito de NR12 novamente para que isso seja concretizado. | E17: Patrick Pessoa | F17: Pequena mudança local | G17: Cost (GE, rework) | H17: 45517.376 | I17: 01. LINHA 01 | J17: 45842.422 | K17: Igor Sousa | L17: IDEIAS-VACUO | M17: 45842.422 | N17: Fechado | O17: =_xlfn.XLOOKUP(TAB.IDEIAS.TOTAL[[#This Row],[Enviado por]],'BASE DMOS'!A:A,'BASE DMOS'!C:C,"Não encontrado") -> OPERAÇÃO
A18: FB0077256 | B18: tambores de capitação de pó filtro de mangas do despredador 1 | C18: Em andamento | D18: Os tambores de capitação de pó do filtro de mangas do despredador 1 estão vazando muito pó porque eles não possuem travas e existe outros tambores que possuem travas e estão desativados porque eram do despredador 2 e hoje não funciona mais, aí poderiam ser substituídos | E18: Valdeci Simoes | F18: Pequena mudança local | G18: Safety - Health | H18: 45518.075 | I18: 01. CAFÉ CRU | J18: 45526.451 | K18: Caique Ventura | L18: IDEIAS-CAFÉ CRÚ | N18: Aguardando Execução | O18: =_xlfn.XLOOKUP(TAB.IDEIAS.TOTAL[[#This Row],[Enviado por]],'BASE DMOS'!A:A,'BASE DMOS'!C:C,"Não encontrado") -> OPERAÇÃO
A19: FB0077257 | B19: suporte de proteção da moega onde joga bags | C19: Resolvido | D19: O novo sistema de entrada de café em bags não possui proteção, podendo amassar a estrutura da moega quando for jogar bag | E19: Valdeci Simoes | F19: Pequena mudança local | G19: Processo | H19: 45518.079 | I19: 01. CAFÉ CRU | J19: 46210.502 | K19: Ruth Alves | L19: APROVADORES DE IDEIAS | N19: Resolvido | O19: =_xlfn.XLOOKUP(TAB.IDEIAS.TOTAL[[#This Row],[Enviado por]],'BASE DMOS'!A:A,'BASE DMOS'!C:C,"Não encontrado") -> OPERAÇÃO
A20: FB0077258 | B20: Tomadas 220 | C20: Em andamento | D20: Colocar pontos de tomada 220 em cima dos silos de grão e pó. Eliézer: é possivel instalar as tomadas porem não temos recursos internos para isso, @leonardo por favor puxar orçamento com Mateus Eletromarzinho | E20: Leonardo Junior | F20: Pequena mudança local | G20: Energy efficiency | H20: 45518.12 | I20: 14. SILOS CAFE MOIDO | J20: 45960.603 | K20: Ana Martins | L20: IDEIAS-PROCESSOS | N20: Aguardando Aprovação de CAPEX | O20: =_xlfn.XLOOKUP(TAB.IDEIAS.TOTAL[[#This Row],[Enviado por]],'BASE DMOS'!A:A,'BASE DMOS'!C:C,"Não encontrado") -> OPERAÇÃO
A21: FB0077552 | B21: descer as válvula de água para baixo | C21: Fechado | D21: A procedimento em desligar o torrador tendo que fecha as válvula do tanque de água ,ao ligar também sendo assim acesso o tanque devido a escada marinheiro precisar fazer pt e wlmra é gera um tempo acha as pessoa responsável para assinar o documento, descendo as válvula para baixo o tempo que gastaria para fazer o documento ganharia em produtividade | E21: Julho Silva | F21: Pequena mudança local | G21: Processo | H21: 45520.408 | I21: 02. TORREFAÇÃO | J21: 45862.592 | K21: Igor Sousa | L21: IDEIAS-PROCESSOS | M21: 45862.592 | N21: Fechado | O21: =_xlfn.XLOOKUP(TAB.IDEIAS.TOTAL[[#This Row],[Enviado por]],'BASE DMOS'!A:A,'BASE DMOS'!C:C,"Não encontrado") -> OPERAÇÃO
A22: FB0077563 | B22: Redução de carreta no pátio | C22: Fechado | D22: Deixar entrar as carretas que estão programadas para descarregar no turno para tirar amostra e não todas do dia as 6h como é hoje. Será necessário priorizar a atividade de tirar amostra logo após contagem de estoque, para não correr risco de atrasos no CQCV. Teremos no máximo 3 carretas no pátio, o que ajuda o almoxarifado ao descarregar cavaco, facilita na gestão de estoque e demais movimentações, além da divisão de atividades entre turnos sobrará tempo para jogar bags e outras atividades no 1 turno | E22: Nilton F Costa | F22: Pequena mudança local | G22: Organisation of work | H22: 45520.483 | I22: 01. CAFÉ CRU | J22: 45595.358 | K22: Sarah Teixeira | L22: IDEIAS-CAFÉ CRÚ | M22: 45595.358 | N22: Fechado | O22: =_xlfn.XLOOKUP(TAB.IDEIAS.TOTAL[[#This Row],[Enviado por]],'BASE DMOS'!A:A,'BASE DMOS'!C:C,"Não encontrado") -> OPERAÇÃO
A23: FB0077783 | B23: Cantoneira para fixar cortina | C23: Cancelado | D23: Seria necessário fixar uma cantoneira para fixação da cortina. Pois toda vez que uma carreta entra na plataforma é preciso segurar parte da cortina para o motorista enxergar a faixa amarela que o auxilia no alinhamento dos pneus da carreta. | E23: Jose Junior | F23: Pequena mudança local | G23: Safety - Health | H23: 45523.728 | I23: 08. LOGISTICA | J23: 45771.477 | L23: IDEIAS-LOGÍSTICA | M23: 45771.477 | N23: Cancelado | O23: =_xlfn.XLOOKUP(TAB.IDEIAS.TOTAL[[#This Row],[Enviado por]],'BASE DMOS'!A:A,'BASE DMOS'!C:C,"Não encontrado") -> OPERAÇÃO
A24: FB0077784 | B24: Sistema de ventilação e exaustão | C24: Em andamento | D24: Nesta área de recebimento das carretas,ao entrar nelas não existe um sistema de circulação de ar,ou exaustor para captar o pó na descarga do café. A falta de uma ventilação eficiente prejudica a respiração e exaustão do corpo,fazendo o operador a suar excessivamente,causando desidratação. SHE: Hiago, o conforto térmico não esta conectado com o projeto ATEX. Eles podem ser desenvolvido juntos mas os objetivos são diferentes. É possivel realizar melhorias na aclimatação do setor. Deevemos fazer uma MOC e na sequencia abrir uma TAP. Do ponto de vista de SHE a ideia está aprovada. | E24: Jose Junior | F24: Pequena mudança local | G24: Safety - Health | H24: 45523.734 | I24: 01. CAFÉ CRU | J24: 46132.775 | K24: Tiago Carvalho | L24: IDEIAS-CAFÉ CRÚ | N24: Aguardando MOC | O24: =_xlfn.XLOOKUP(TAB.IDEIAS.TOTAL[[#This Row],[Enviado por]],'BASE DMOS'!A:A,'BASE DMOS'!C:C,"Não encontrado") -> OPERAÇÃO
A25: FB0078291 | B25: Aumento de capacidade de estoque de café cru | C25: Fechado | D25: Atualmente armazenamos 1000kg de café em cada bag, com isso sobra um espaço vazio em cada bag. A proposta é aumentar para 1100kg em cada bag, respeitando sua capacidade máxima de armazenamento. Solicitar ao Michel EGE para configurar a quantidade de café na retirada de bag. | E25: Nilton F Costa | F25: Pequena mudança local | G25: Organisation of work | H25: 45527.302 | I25: 01. CAFÉ CRU | J25: 45639.628 | K25: Sarah Teixeira | L25: IDEIAS-CAFÉ CRÚ | M25: 45639.628 | N25: Fechado | O25: =_xlfn.XLOOKUP(TAB.IDEIAS.TOTAL[[#This Row],[Enviado por]],'BASE DMOS'!A:A,'BASE DMOS'!C:C,"Não encontrado") -> OPERAÇÃO
A26: FB0078586 | B26: fechador de abas | C26: Fechado | D26: confecção de um nomo modelo de fechador de abas para encaixotadora mais simples e eficaz | E26: Arthur Silva | F26: Pequena mudança local | G26: Product | H26: 45530.475 | I26: 01. LINHA 01 | J26: 45594.58 | L26: IDEIAS-VACUO | M26: 45594.58 | N26: Fechado | O26: =_xlfn.XLOOKUP(TAB.IDEIAS.TOTAL[[#This Row],[Enviado por]],'BASE DMOS'!A:A,'BASE DMOS'!C:C,"Não encontrado") -> ADM/TÉCNICO/ASSISTENTE/ESTAG.
A27: FB0078785 | B27: Programa de apadrinhamento da operação pela manutenção | C27: Em andamento | D27: IDEIA Criar um programa onde os associados que estão fazendo ou já fizeram curso técnico de eletrônico e mecânico sejam apadrinhados pelos manutentores na execução de atividades em paradas e preventivas possibilitando transferência de conhecimento e preparação para próximas oportunidades. --------------------- FEEDBACK Edvan, obrigada pela ideia. Vamos ver como conseguimos incorporar isso integrando o pilar de MA e ORG. A Luzia vai verificar. (Lu, analisar por favor e colocar em pauta para algum desses pilares) FEEDBACK 23/09/2025: Creio que seja uma ótima oportunidade de aprendizado mas que precisará de um plano para garantir oportunidades igualitárias sem que impacte as atividades operacionais e manutenções. Levarei para o pilar Org, creio ser uma frente de trabalho possível para 2026. FEEDBACK 28/05/2026: Atribuindo e encaminhando à Fabrizia para que analise e veja se é possível levar o tema no pilar org ou se não está alinhado a estratégia do momento. | E27: Edvan Santos | F27: Pequena mudança local | G27: Organisation of work | H27: 45532.233 | I27: 01. TORRADORES | J27: 46206.451 | K27: Fabrizia Soares | L27: APROVADORES DE IDEIAS | N27: Aguardando Execução | O27: =_xlfn.XLOOKUP(TAB.IDEIAS.TOTAL[[#This Row],[Enviado por]],'BASE DMOS'!A:A,'BASE DMOS'!C:C,"Não encontrado") -> OPERAÇÃO
A28: FB0081067 | B28: testador de vácuo PKD | C28: Resolvido | D28: O testador de vácuo está amaçando o pacote durante o teste de pressão . Com esse amaçado o pacote ganha uma inclinação vindo a escorregar na encaixotadora e também podendo rasgar a caixa durante o enchimentos devido a forma que fundo do pacote fica. Realizar uma melhoria no stop do testador afim que a chapa que segura o pacote não encline para não amassar o pacote. Ideia discutida com Arthur da manutenção | E28: Patrick Pessoa | F28: Pequena mudança local | G28: Qualidade | H28: 45546.514 | I28: 01. LINHA 01 | J28: 46049.549 | K28: Henrique Cardoso | L28: IDEIAS-VACUO | N28: Resolvido | O28: =_xlfn.XLOOKUP(TAB.IDEIAS.TOTAL[[#This Row],[Enviado por]],'BASE DMOS'!A:A,'BASE DMOS'!C:C,"Não encontrado") -> OPERAÇÃO | P28: CANCELADO
A29: FB0081758 | B29: Substituir as lixeiras sem cor por lixeiras com a cor da soleta seletiva | C29: Cancelado | D29: Por 5S, a sugestão é substituirmos as lixeiras por lixeiras novas nas linhas de acordo com as cores da coleta seletiva (igual tem na logísitca). Elas não ficam encardidas. Não precisa trocar agora, mas na próxima substituição considerar esse modelo. | E29: Giovanna Biffaratte | F29: Pequena mudança local | G29: Organisation of work | H29: 45552.915 | I29: 04. EMPACOTAMENTO | J29: 45770.462 | L29: APROVADORES DE IDEIAS | M29: 45770.462 | N29: Cancelado | O29: =_xlfn.XLOOKUP(TAB.IDEIAS.TOTAL[[#This Row],[Enviado por]],'BASE DMOS'!A:A,'BASE DMOS'!C:C,"Não encontrado") -> ADM/TÉCNICO/ASSISTENTE/ESTAG.
A30: FB0082056 | B30: Plano fixo de Cafés | C30: Cancelado | D30: Fixar o plano de cafés nas fabrimas, onde as fabrimas 4 e 5 produziriam café de canaleta fechada, que é o tipo de café que tem a melhor performance nas máquinas. E as fabrimas 2 e 3 produziriam cafés de canaletas abertas, que é o tipo de café que produz melhor nas máquinas. (Aberto a opiniões) | E30: Rafael Santos | F30: Pequena mudança local | G30: Cost (GE, rework) | H30: 45554.822 | I30: 04. EMPACOTAMENTO | J30: 45770.631 | L30: APROVADORES DE IDEIAS | M30: 45770.631 | N30: Cancelado | O30: =_xlfn.XLOOKUP(TAB.IDEIAS.TOTAL[[#This Row],[Enviado por]],'BASE DMOS'!A:A,'BASE DMOS'!C:C,"Não encontrado") -> OPERAÇÃO
A31: FB0082999 | B31: Apoio fixo (pé fixo) | C31: Cancelado | D31: Soldar 5 apoio fixo com 15 cm de altura sendo dois em cada lado e um no meio Vejo que é recorrente a quebra das rodas sendo com apoio fixo não teremos mais ocorrência de quebra e com isso iremos economizar pois cada roda custa em média 700.00 cada E soldando pés teríamos pouco gastos | E31: Joelma Inone | F31: Pequena mudança local | G31: Organisation of work | H31: 45562.775 | I31: 01. LINHA 01 | J31: 45704.584 | L31: IDEIAS-VACUO | M31: 45704.584 | N31: Cancelado | O31: =_xlfn.XLOOKUP(TAB.IDEIAS.TOTAL[[#This Row],[Enviado por]],'BASE DMOS'!A:A,'BASE DMOS'!C:C,"Não encontrado") -> OPERAÇÃO
A32: FB0083266 | B32: colocar o torrador 3 para torra super claro | C32: Fechado | D32: Mesmo quando os torradores turbo 1 e 2 tiver funcionando,ligaria o torrador 3 para fazer o super claro ganharíamos na produtividade e acompanharia a máquina sempre em funcionamento não ficaria grandes período desligado não sujeitando problemas e perda de café quando precisar da máquina ela não ficará grandes período desligada , não consumiria muito o gás pq ligaria por pequeno período só para abastecer o super claro qualquer defeito seria identificado se caso problema no torrador 1 e 2 a máquina 3 estaria pronta para produzir integralmente | E32: Julho Silva | F32: Pequena mudança local | G32: Processo | H32: 45566.526 | I32: 03. TORRADOR 03 | J32: 45861.307 | K32: Igor Sousa | L32: IDEIAS-PROCESSOS | M32: 45861.307 | N32: Fechado | O32: =_xlfn.XLOOKUP(TAB.IDEIAS.TOTAL[[#This Row],[Enviado por]],'BASE DMOS'!A:A,'BASE DMOS'!C:C,"Não encontrado") -> OPERAÇÃO | P32: CANCELADO
A33: FB0083468 | B33: '+ aspirador de pó | C33: Fechado | D33: Comprar + aspirador de pó para fabrimas, para economizar tempo de cil, pois como possui apenas 1 aspirador pra 2 máquinas, sendo que uma pessoa tem q esperar desocupar o aspirador para poder usar | E33: Romero Chaves | F33: Pequena mudança local | G33: Organisation of work | H33: 45568.568 | I33: 04. LINHA 04 | J33: 45909.478 | L33: APROVADORES DE IDEIAS | M33: 45909.478 | N33: Fechado | O33: =_xlfn.XLOOKUP(TAB.IDEIAS.TOTAL[[#This Row],[Enviado por]],'BASE DMOS'!A:A,'BASE DMOS'!C:C,"Não encontrado") -> OPERAÇÃO
A34: FB0083992 | B34: Lixeira integrada na bancada para otimização de espaço | C34: Cancelado | D34: Fazer um furo com o devido acabamento no granito das bancadas da barreira sanitária para colocar as lixeiras de papel toalha embaxio da bancada e liberar espaço visto que as lixeiras estão muito proximas da catraca da barreira sanitária. Também poderia ser feito nos banheiros visto que principalmente no feminino a localização atual da lixeira pode dificultar um pouco o transito na porta do banheiro. Sugestão nas imagens em anexo As lixeiras podem ter tampas giratórias/basculantes (semelhantes como são as lixeiras inox do adm) embutidas na bancada para atender os requistos de qualidade e não ficarem abertas. | E34: Luzia Rodrigues | F34: Pequena mudança local | G34: Organisation of work | H34: 45573.612 | I34: 09.5 BANHEIROS | J34: 45797.365 | L34: IDEIAS-ADMINISTRATIVO | M34: 45797.365 | N34: Cancelado | O34: =_xlfn.XLOOKUP(TAB.IDEIAS.TOTAL[[#This Row],[Enviado por]],'BASE DMOS'!A:A,'BASE DMOS'!C:C,"Não encontrado") -> ADM/TÉCNICO/ASSISTENTE/ESTAG.
A35: FB0084063 | B35: alteração na descrição das receitas | C35: Fechado | D35: Algumas receitas não contém o número do Blend,por exemplo Damasco tradicional (Blend 40) | E35: Lucas Vaz | F35: Pequena mudança local | G35: Qualidade | H35: 45574.019 | I35: 02. TORREFAÇÃO | J35: 45846.368 | K35: Igor Sousa | L35: IDEIAS-PROCESSOS | M35: 45846.368 | N35: Fechado | O35: =_xlfn.XLOOKUP(TAB.IDEIAS.TOTAL[[#This Row],[Enviado por]],'BASE DMOS'!A:A,'BASE DMOS'!C:C,"Não encontrado") -> OPERAÇÃO
A36: FB0084739 | B36: filtrar paradas do robô | C36: Fechado | D36: IDEIA Filtrar as paradas do robô , mudando a cor das paradas ex: ( amarelo) , está dificultando muito para separar as paradas para fechar o relatório no final do turno . ------------- APROVAÇÃO Angela, excelente ideia. Demoramos para implantar, pois desde novembro estamos sem o orçamento para melhorias no MOP. Ele foi reativado agora em abril e já encaminhamos sua ideia na lista de solicitações. Para conhecimento, esse orçamento nos permite usar 3 diárias mensais de serviço especializado para alguma melhoria no MOP, então às vezes se já usamos as diárias, precisamos esperar o próximo mês para pedir algo novo. | E36: Angela Santos | F36: Pequena mudança local | G36: Cost (GE, rework) | H36: 45575.001 | I36: 04. LINHA 04 | J36: 45821.03 | K36: Giovanna Biffaratte | L36: APROVADORES DE IDEIAS | M36: 45821.03 | N36: Fechado | O36: =_xlfn.XLOOKUP(TAB.IDEIAS.TOTAL[[#This Row],[Enviado por]],'BASE DMOS'!A:A,'BASE DMOS'!C:C,"Não encontrado") -> OPERAÇÃO
A37: FB0084748 | B37: Adicionar no CIL mensal para limpeza dos utensílios de limpeza das areas | C37: Fechado | D37: Devido ao acumulo de sujeira, adicionar no CIL mensal a limpeza dos utensílios de limpeza com água ou pano. | E37: Bianca Silva | F37: Pequena mudança local | G37: Qualidade | H37: 45575.055 | I37: 01. LINHA 01 | J37: 45846.368 | K37: Bianca Silva | L37: IDEIAS-VACUO | M37: 45846.368 | N37: Fechado | O37: =_xlfn.XLOOKUP(TAB.IDEIAS.TOTAL[[#This Row],[Enviado por]],'BASE DMOS'!A:A,'BASE DMOS'!C:C,"Não encontrado") -> ADM/TÉCNICO/ASSISTENTE/ESTAG.
A38: FB0084875 | B38: Canetas sempre no chão | C38: Fechado | D38: As canetas do quadro da moagem sempre caíam, foi feito um suporte(paleativo), para acabar com este problema | E38: Camila Silva | F38: Pequena mudança local | G38: Organisation of work | H38: 45575.42 | I38: 03. MOAGEM | J38: 45595.357 | K38: Camila Silva | L38: IDEIAS-PROCESSOS | M38: 45595.357 | N38: Fechado | O38: =_xlfn.XLOOKUP(TAB.IDEIAS.TOTAL[[#This Row],[Enviado por]],'BASE DMOS'!A:A,'BASE DMOS'!C:C,"Não encontrado") -> OPERAÇÃO
A39: FB0085512 | B39: Abridor de Abas | C39: Fechado | D39: Realizar alteração no tempo de atuação do abridor de abas fazendo com que ele não entre junto com chapa frontal do enchedor para que não aja colisão na caixa fora do tempo e assim a caixa fica parada não movimento nem para traz ou para frente Ideia já discutido com Igor Eletrônico | E39: Patrick Pessoa | F39: Pequena mudança local | G39: Cost (GE, rework) | H39: 45581.419 | I39: 01. LINHA 01 | J39: 45594.544 | L39: IDEIAS-VACUO | M39: 45594.544 | N39: Fechado | O39: =_xlfn.XLOOKUP(TAB.IDEIAS.TOTAL[[#This Row],[Enviado por]],'BASE DMOS'!A:A,'BASE DMOS'!C:C,"Não encontrado") -> OPERAÇÃO
A40: FB0085628 | B40: melhoria procedimento quando arrebenta a alça do bag | C40: Em andamento | D40: quando arrebenta uma alça de bag hoje amarramos a alça com corda reaproveitada da caçamba do cavaco conforme foto. para melhorar a situação de segurança favor comprar uma cinta de 1.5m com capacidade 1500kg para está ser usada no alcamento do bag (considerando as outras 3 alças restante) Pedro Ferreira: Ideia apta para execução, mas é necessário que o orçamento seja enviado até CI, para que seja efetuada a compra. | F40: Pequena mudança local | G40: Safety - Health | H40: 45582.379 | I40: 01. CAFÉ CRU | J40: 46238.61 | K40: Flavia Silveira | L40: APROVADORES DE IDEIAS | N40: Aguardando material | O40: =_xlfn.XLOOKUP(TAB.IDEIAS.TOTAL[[#This Row],[Enviado por]],'BASE DMOS'!A:A,'BASE DMOS'!C:C,"Não encontrado") -> 0
...

Sheet % Operação x adm
A1: Meses (Criada) | B1: (Vários itens)
A2: Anos (Criada) | B2: 2026
B4: Rótulos de Coluna
B5: ADM/TÉCNICO/ASSISTENTE/ESTAG. | C5: OPERAÇÃO | D5: Total Geral
A6: Contagem de Enviado por | B6: 92 | C6: 92 | D6: 184
A8: ADM/TÉCNICO/ASSISTENTE/ESTAG. | B8: 50
A9: OPERAÇÃO | B9: 95
C11: Mais de 50% das ideias criadas por Operação

Sheet Taxa de Implementação
A3: Aprovadas | B3: Canceladas/ Rascunho
A4: 58 | B4: 55
B5: 2025-2026 ATUALIZADAS | E5: SÓ 2026
B6: Ideias Implementadas | C6: Ideias Aprovadas | E6: Ideias Implementadas | F6: Ideias Aprovadas
B7: 103 | C7: 181 | E7: 36 | F7: 82
B8: Implementadas/total de ideias aprovadas | C8: =B7/C7 -> 0.56906077 | E8: Implementadas/total de ideias aprovadas | F8: =E7/F7 -> 0.43902439
A11: Nivel 2 | B11: Precisamos mais que 50% de ideias implementadas/executadas
A12: Nivel 3 | B12: Precisamos mais que 80% de ideias implementadas/executadas

Sheet Ideias por categorias
A1: Anos (Criada) | B1: 2026
A3: Contagem de Sub categoria | B3: Rótulos de Coluna
A4: Rótulos de Linha | B4: INVALUABLE | C4: IN PROGRESS | D4: CLOSED | E4: REALIZED | F4: Total Geral
A5: Cost (GE, rework) | B5: 3 | C5: 10 | D5: 1 | E5: 6 | F5: 20
A6: Energy efficiency | D6: 1 | F6: 1
A7: Meio Ambiente | E7: 1 | F7: 1
A8: Organisation of work | B8: 8 | C8: 15 | D8: 1 | E8: 14 | F8: 38
A9: Processo | B9: 5 | C9: 7 | D9: 2 | E9: 10 | F9: 24
A10: Product | B10: 1 | C10: 1 | E10: 1 | F10: 3
A11: Qualidade | B11: 3 | C11: 7 | E11: 5 | F11: 15
A12: Safety - Health | B12: 9 | C12: 11 | D12: 1 | E12: 6 | F12: 27
A13: Yeld | C13: 2 | E13: 1 | F13: 3
A14: New software | E14: 2 | F14: 2
A15: Total Geral | B15: 29 | C15: 53 | D15: 6 | E15: 46 | F15: 134
A17: Rótulos de Linha | B17: INVALUABLE | C17: IN PROGRESS | D17: REALIZED
A18: Cost (GE, rework) | B18: 3 | C18: 8 | D18: 7
A19: Meio Ambiente | D19: 2
A20: Organisation of work | B20: 4 | C20: 10 | D20: 7
A21: Processo | B21: 5 | C21: 7 | D21: 10
A22: Product | B22: 1 | C22: 1 | D22: 1
A23: Qualidade | B23: 2 | C23: 8 | D23: 4
A24: Safety - Health | B24: 8 | C24: 10 | D24: 4
A25: Yeld | C25: 2 | D25: 1

Sheet Ideias por associado
A2: Criada | B2: (Tudo) | D2: Associado que criaram ideia | E2: Assosciados que não criaram ideias | F2: Total FTE | G2: Total ideias criadas | H2: % de ideias por FTE
C3: FTE faltantes | D3: 56 | E3: =F3-D3 -> 66 | F3: 122 | G3: 136 | H3: =G3/F3 -> 1.1147541
A4: Rótulos de Linha | B4: Contagem de Status | C4: Alex Wilson Jose Bernardes
A5: Alex Teixeira | B5: 1 | C5: Alexandre Da Costa Araujo
A6: Aline Fernandes | B6: 9 | C6: Ana Luisa Figueiredo Silva
A7: Ana Martins | B7: 1 | C7: Ana Luiza Paula
A8: Ana Pereira | B8: 1 | C8: Ana Maria da Silva
A9: Angela Santos | B9: 5 | C9: Andre Campos
A10: Bianca Silva | B10: 4 | C10: Bruna Santos
A11: Camila Silva | B11: 1 | C11: Caio Ferreira
A12: Daniela Alves | B12: 1 | C12: Caluan Guimaraes
A13: Edvaldo Silva | B13: 3 | C13: Camila Brasilia
A14: Emilly Silva | B14: 3 | C14: Camila Franco
A15: Fabio S Santos | B15: 8 | C15: Carlos Souza
A16: Fabricio Brant | B16: 7 | C16: Daniel Madureira | H16: Nível 3 | I16: Precisamos de 0,3 de ideias criadas por 1FTE
A17: Giovanna Biffaratte | B17: 6 | C17: Daniel Seri
A18: Isaias Macedo | B18: 1 | C18: DEIVISON SOUZA ALVES CHAVES
A19: Jhonnathan Pereira | B19: 1 | C19: Deusmira Lima
A20: Joelma Inone | B20: 3 | C20: Deyvidson Dos Santos
A21: Karina Silva | B21: 2 | C21: Ednaldo L Silva | D21: Nível 2 | E21: Precisamos de 50% de FTE tenha criado pelo menos 1 ideia
A22: Lucas Vaz | B22: 1 | C22: Eduardo Candido | D22: Nível 3 | E22: Precisamos de 70% de FTE tenha criado pelo menos 1 ideia
A23: Luiz H Silva | B23: 2 | C23: Eduardo Santos
A24: Luzia Rodrigues | B24: 1 | C24: Edvan Santos
A25: Michelle Faria | B25: 3 | C25: EVANIO SANTOS
A26: Moises Costa | B26: 5 | C26: Fabio A Oliveira
A27: Nilton F Costa | B27: 1 | C27: FABIO COELHO
A28: Patrick Pessoa | B28: 3 | C28: Fabrizia Soares
A29: Rafael Santos | B29: 3 | C29: Felipe Simoes
A30: Romilda Cunha | B30: 5 | C30: Gian Silva
A31: Ruth Ribeiro | B31: 4 | C31: Gilberto Rodrigues de Melo
A32: Sara Lobato | B32: 1 | C32: Guilherme P Silva
A33: Thais Souza | B33: 4 | C33: Gustavo Rodrigues
A34: Tiago Carvalho | B34: 3 | C34: Henrique Cardoso
... A62: Total Geral | B62: 184 | C62: Tais Costa
C63: Talita Campos
C64: Thaissa Oliveira
C65: Vicente P Silva
C66: Vilbert Santos
C67: Vinicius de Moraes
C68: Vitor Xavier
...

Sheet Ideias-area
A1: Anos (Criada) | B1: 2026
A2: Meses (Criada) | B2: (Vários itens) | L2: CAFÉ CRU | M2: 9
L3: JDE CAFES DO BRASIL UNIDADE PIUMHI | M3: 9
A4: Rótulos de Linha | B4: Contagem de Área de trabalho | L4: TORRADORES | M4: 12
A5: 01. CAFÉ CRU | B5: 9 | L5: MOAGEM | M5: 8
A6: 01. JDE CAFES DO BRASIL UNIDADE PIUMHI | B6: 19 | L6: EMPACOTAMENTO | M6: 70
A7: 01. LINHA 01 | B7: 28 | L7: ADMINISTRATIVO | M7: 22
A8: 01. TORRADORES | B8: 5 | L8: LOGISTICA | M8: 1
A9: 02. LINHA 02 | B9: 9 | L9: SALA DE PRODUTOS QUÍMICOS | M9: 13
A10: 02. TORREFAÇÃO | B10: 9
A11: 03. CABLEVEY | B11: 2
A12: 03. MOAGEM | B12: 5
A13: 04. EMPACOTAMENTO | B13: 27
A14: 04. LINHA 04 | B14: 10
A15: 05. LINHA 05 | B15: 8
A16: 06. ADMINISTRATIVO | B16: 18
A17: 06. PALETIZADORAS DE FARDOS | B17: 1
A18: 08. BIOMASSA | B18: 2
A19: 08. LOGISTICA | B19: 3
A20: 09.10 Escritórios administrativos | B20: 7
A21: 09.17 REFEITÓRIO | B21: 2
... A28: 07. AREAS EXTERNAS | B28: 2
A29: Total Geral | B29: 184 | L29: CAFÉ CRU | M29: 21
L30: JDE CAFES DO BRASIL UNIDADE PIUMHI | M30: 27
L31: TORRADORES | M31: 28
L32: MOAGEM | M32: 21
L33: EMPACOTAMENTO | M33: 174
L34: ADMINISTRATIVO | M34: 28
L35: LOGISTICA | M35: 10
L36: SALA DE PRODUTOS QUÍMICOS | M36: 16

Sheet CADASTRO
A1: NOME | B1: TURNO COMP | C1: TURNO | D1: COORDENADOR | E1: FUNÇÃO | F1: STATUS | G1: ÁREA | H1: IDFIXO
A2: ABNER BARROS DE PAIVA | B2: 3º turno - 6x1 - 22:00 ás | C2: 3 | D2: LEONARDO ANTONIO FRANCELINO JUNIOR | E2: OPERADOR INDUSTRIAL I | F2: ATIVO | G2: FABRIMA | H2: 191
A3: ALEX BARBARA | B3: 1º Turno - 6x2 06:00 - 14 | C3: 1 | D3: HENRIQUE MARTINS CARDOSO | E3: TECNICO MECANICO II | F3: ATIVO | G3: MANUTENÇÃO | H3: 188
A4: ALEX SANDRO ALVES TEIXEIRA | B4: 2º turno - 6x1 - 14:00 ás | C4: 2 | D4: MICHELLE APARECIDA FARIA | E4: OPERADOR INDUSTRIAL II | F4: ATIVO | G4: MOINHO | H4: 190
A5: ALEXANDRE BATISTA DE OLIVEIRA | B5: 1º Turno - 6x2 06:00 - 14 | C5: 1 | D5: HENRIQUE MARTINS CARDOSO | E5: TECNICO MECANICO III | F5: ATIVO | G5: MANUTENÇÃO | H5: 192
A6: ALEXANDRE DE ASSIS DA COSTA | B6: 3º Turno - 6x2 22:00 - 06 | C6: 3 | D6: HENRIQUE MARTINS CARDOSO | E6: TECNICO MECANICO II | F6: ATIVO | G6: MANUTENÇÃO | H6: 205
A7: ALICE RAMOS MORAIS | B7: 0- ADM- SEG/SEX 08:30 ÀS | C7: 0 | D7: CAIO GUILHERME SALES FERREIRA | E7: ANALISTA GESTAO QUALIDADE PL | F7: ATIVO | G7: QUALIDADE | H7: 194
A8: ALINE FERNANDES | B8: 0 - ADM - SEG / SEX 08:00 | C8: 0 | D8: SARAH FELICIO TEIXEIRA | E8: ASSISTENTE ADMINISTRATIVO | F8: ATIVO | G8: ALMOXARIFADO | H8: 195
A9: ANA BEATRIZ LIMA SILVA | B9: 0 - ADM - SEG/SEX 08:30 A | C9: 0 | D9: CAIO GUILHERME SALES FERREIRA | E9: ESTAGIARIO | F9: ATIVO | G9: QUALIDADE | H9: 309
A10: ANA CAROLLINE SIQUEIRA MARTINS | B10: 0- ADM- SEG/SEX 08:30 ÀS | C10: 0 | D10: ELIEZER SILVA | E10: ASSISTENTE ADMINISTRATIVO | F10: ATIVO | G10: MANUTENÇÃO ADM | H10: 196
A11: ANA JULIA COSTA SILVA | B11: 2º turno - 6x1 - 14:00 ás | C11: 2 | D11: IZABELA CAROLINE PUGLIESI | E11: OPERADOR INDUSTRIAL I | F11: ATIVO | G11: FABRIMA | H11: 197
A12: ANA LUISA FIGUEIREDO SILVA | B12: HIRE NOW | C12: H | D12: ELIEZER SILVA | E12: ASSISTENTE ADMINISTRATIVO | F12: ATIVO | G12: MANUTENÇÃO ADM | H12: 198
A13: ANA LUISA SOARES PEREIRA | B13: 0 - ADM - SEG / SEX 08:00 | C13: 0 | D13: DANIEL SERI | E13: ANALISTA FACILITIES | F13: ATIVO | G13: FACILITIES | H13: 199
... A122: WILGNER REBERTE TAYLON DA SILVA | B122: 2º turno - 6x1 - 14:00 ás | C122: 2 | D122: IZABELA CAROLINE PUGLIESI | E122: AUXILIAR INDUSTRIAL | F122: ATIVO | G122: FABRIMA | H122: 307

Sheet BASE DMOS
A1: Base DMOS | B1: NOME | C1: TIPO | D1: CARGO | E1: AREA | F1: COORDENADOR | G1: SITUAÇÃO
A2: Angela Santos | B2: ANGELA ALVES DOS SANTOS | C2: OPERAÇÃO | D2: OPERADOR INDUSTRIAL II | E2: EMPACOTAMENTO | F2: RELTON FERREIRA DE MORAES | G2: ATIVO
A3: Alex Barbara | B3: ALEX BARBARA | C3: ADM/TÉCNICO/ASSISTENTE/ESTAG. | D3: TECNICO MECANICO II | E3: MANUTENÇÃO | F3: HENRIQUE MARTINS CARDOSO | G3: ATIVO
A4: Carlos Souza | B4: CARLOS INACIO PEREIRA DE SOUZA | C4: OPERAÇÃO | D4: OPERADOR INDUSTRIAL I | E4: EMPACOTAMENTO | F4: LEONARDO ANTONIO FRANCELINO JUNIOR | G4: ATIVO
A5: Alex Wilson Jose Bernardes | B5: ALEX WILSON JOSE BERNARDES | C5: OPERAÇÃO | D5: OPERADOR LOGISTICO I | E5: LOGÍSTICA | F5: FABIO ASSIS DE OLIVEIRA | G5: DESLIGADO
A6: Alexandre Oliveira | B6: ALEXANDRE BATISTA DE OLIVEIRA | C6: ADM/TÉCNICO/ASSISTENTE/ESTAG. | D6: TECNICO MECANICO III | E6: MANUTENÇÃO | F6: HENRIQUE MARTINS CARDOSO | G6: ATIVO
A7: Alexandre Da Costa Araujo | B7: ALEXANDRE DE ASSIS DA COSTA | C7: ADM/TÉCNICO/ASSISTENTE/ESTAG. | D7: TECNICO MECANICO II | E7: MANUTENÇÃO | F7: HENRIQUE MARTINS CARDOSO | G7: ATIVO
A8: Alice Morais | B8: ALICE RAMOS MORAIS | C8: ADM/TÉCNICO/ASSISTENTE/ESTAG. | D8: ANALISTA GESTAO QUALIDADE PL | E8: QUALIDADE | F8: COORDENADOR DE QUALIDADE | G8: ATIVO
A9: Aline Fernandes | B9: ALINE FERNANDES | C9: ADM/TÉCNICO/ASSISTENTE/ESTAG. | D9: ASSISTENTE ADMINISTRATIVO | E9: ALMOXARIFADO | F9: SARAH FELICIO TEIXEIRA | G9: ATIVO
A10: Ana Martins | B10: ANA CAROLLINE SIQUEIRA MARTINS | C10: ADM/TÉCNICO/ASSISTENTE/ESTAG. | D10: ASSISTENTE ADMINISTRATIVO | E10: MANUTENÇÃO | F10: ELIEZER SILVA | G10: ATIVO
A11: Daniel Madureira | B11: DANIEL ALMEIDA MADUREIRA | C11: OPERAÇÃO | D11: OPERADOR INDUSTRIAL II | E11: MOAGEM | F11: MICHELLE APARECIDA FARIA | G11: ATIVO
A12: Ana Luisa Figueiredo Silva | B12: ANA LUISA FIGUEIREDO SILVA | C12: ADM/TÉCNICO/ASSISTENTE/ESTAG. | D12: ASSISTENTE ADMINISTRATIVO | E12: MANUTENÇÃO | F12: ELIEZER SILVA | G12: ATIVO
... A157: Leandro Freire | B157: LEANDRO DE PAULA FREIRE | C157: ADM/TÉCNICO/ASSISTENTE/ESTAG. | D157: ANALISTA MANUTENCAO JR | E157: MANUTENÇÃO ADM | F157: ELIEZER SILVA | G157: DESLIGADO
